Workbook
Name Slicer_Course_Type_Clean: #N/A
Name Slicer_Learning_Mode_Clean: #N/A
Name Slicer_State_Clean: #N/A

Sheet Raw_Data
A1: Student_ID | B1: Name | C1: Age | D1: Gender | E1: City | F1: State | G1: Course_Type | H1: Learning_Center | I1: Enrolled_Since | J1: Parent_Occupation | K1: Age_Group | L1: Age Category | M1: Learner_Category | N1: Learning_Mode_Used | O1: Fee_Paid | P1: Avg_Monthly_Study_Hours | Q1: Fee_Outstanding | R1: Subscription_Status | S1: Performance_Score | T1: Sessions_Attended | U1: App_Usage | V1: Web_Usage | W1: Satisfaction_Score | X1: Learning_Tenure_Years
A2: BYJ1001 | B2: Aryan Maharaj | D2: female | E2: Rajahmundry | F2: Karnataka | G2: Mathematics | H2: Lucknow Hub | I2: 2022 | J2: Business | M2: PREMIUM LEARNER | N2: Both App & Web | O2: 33831.46 | P2: 45.9 | Q2: 13226.44 | R2: NONE | S2: 306 | T2: 40 | U2: N | V2: no | W2: 2 | X2: 8.6
A3: BYJ1002 | B3: Harsh Chahal | C3: 12 | D3: F | E3: Patna | F3: Tamil Nadu | G3: Spoken English | H3: Jaipur Center | I3: 03-07-2017 | J3: Retired | K3: 10-13 | L3: Kids | M3: NON PREMIUM LEARNER | N3: Both App & Web | O3: 32881.85 | P3: 54.6 | Q3: 46384.1 | R3: active | S3: 403 | T3: 116 | U3: no | V3: N | W3: 2 | X3: 6.2
A4: BYJ1003 | B4: Girik Kamdar | C4: 10 | D4: MALE | E4: Dibrugarh | F4: Maharashtra | G4: Spoken English | H4: Kolkata Main | I4: 2020-11-23 | J4: Retired | K4: 10-13 | L4: Kids | M4: NON PREMIUM LEARNER | N4: App Only | O4: 38211.97 | P4: 28.7 | Q4: 16064.45 | R4: ACTIVE | S4: 517 | T4: 101 | U4: no | V4: no | W4: 2 | X4: 6.8
A5: BYJ1004 | B5: Rushil Saini | C5: 33 | D5: F | E5: Sultan Pur Majra | F5: Maharashtra | G5: Spoken English | H5: Bengaluru South | I5: 2016-02-05 | J5: Retired | K5: 20+ | L5: Adult Learners | M5: Non Premium Learner | N5: Web Only | O5: 91403.82 | P5: 23.9 | Q5: 33193.55 | R5: Active | S5: 849 | T5: 196 | U5: No | V5: No | W5: 2 | X5: 4.4
A6: BYJ1005 | B6: Abeer Dutta | C6: 22 | D6: MALE | E6: Mau | F6: Telangana | G6: English | H6: Mumbai West | I6: 2021 | J6: Government Employee | K6: 20+ | L6: Adult Learners | M6: Non Premium Learner | N6: Web Only | O6: 132414.67 | P6: 28.1 | Q6: 3475.51 | R6: None | S6: 387 | T6: 17 | U6: yes | V6: no | W6: 3 | X6: 5
A7: BYJ1006 | B7: Nachiket Kale | C7: 40 | D7: M | E7: Kota | F7: Gujarat | G7: Spoken English | H7: Jaipur Center | I7: 2023-02-08 | J7: Salaried | K7: 20+ | L7: Adult Learners | M7: NON PREMIUM LEARNER | N7: App Only | P7: 58.1 | Q7: 3532.43 | R7: Active | S7: 638 | T7: 60 | U7: No | V7: yes | W7: 5 | X7: 5.4
A8: BYJ1007 | B8: Lajita Chatterjee | C8: 32 | D8: Male | E8: Hapur | F8: West Bengal | G8: NEET Prep | H8: Kolkata Main | I8: 2022 | J8: Retired | K8: 20+ | L8: Adult Learners | M8: NON PREMIUM LEARNER | N8: App Only | O8: 63380.09 | P8: 69.6 | Q8: 14919.38 | R8: Active | S8: 443 | T8: 71 | U8: no | V8: Yes | W8: 5 | X8: 1.3
A9: BYJ1008 | B9: Caleb Sharaf | C9: 6 | D9: male | E9: Burhanpur | F9: Rajasthan | G9: Spoken English | H9: Delhi North | I9: Jan 2022 | J9: Salaried | K9: Under 10 | L9: Kids | M9: NON PREMIUM LEARNER | N9: Web Only | O9: 46361.14 | P9: 59.8 | Q9: 47001.69 | R9: NIL | S9: 458 | T9: 55 | U9: Yes | V9: No | W9: 1 | X9: 5.5
A10: BYJ1009 | B10: Chaaya Pathak | C10: 16 | D10: MALE | E10: Coimbatore | F10: Maharashtra | G10: Mathematics | H10: Lucknow Hub | I10: 2017-11-28 | J10: Self-Employed | K10: 14-16 | L10: Teens | M10: PREMIUM LEARNER | N10: App Only | O10: 88943.26 | P10: 11.1 | Q10: 39442.39 | S10: 623 | T10: 52 | U10: no | V10: No | W10: 2 | X10: 6.2
A11: BYJ1010 | B11: Vedant Mann | C11: 10 | D11: Male | E11: Muzaffarpur | F11: Kerala | G11: Mathematics | H11: Bengaluru South | I11: 17-04-2024 | J11: Business | K11: 10-13 | L11: Kids | M11: NON PREMIUM LEARNER | N11: App Only | O11: 58581.43 | P11: 67.5 | Q11: 42212.4 | S11: 308 | T11: 141 | U11: No | V11: Y | W11: 1 | X11: 8.1
A12: BYJ1011 | B12: Lajita Mall | C12: 24 | D12: M | E12: Bharatpur | F12: Telangana | G12: Spoken English | H12: Hyderabad Hub | I12: Feb 2016 | J12: Homemaker | K12: 20+ | L12: Adult Learners | M12: PREMIUM LEARNER | N12: App Only | O12: 97381.44 | P12: 60.6 | Q12: 33100.83 | R12: CLOSED | S12: 309 | T12: 176 | U12: Yes | V12: no | W12: 4 | X12: 1.6
A13: BYJ1012 | B13: Kamala Pant | C13: 8 | D13: female | E13: Shimoga | F13: Karnataka | G13: NEET Prep | H13: Jaipur Center | I13: 2022-10-24 | J13: Business | K13: Under 10 | L13: Kids | M13: NON PREMIUM LEARNER | N13: App Only | O13: 132805.35 | P13: 60.2 | Q13: 19931.13 | R13: CLOSED | S13: 554 | T13: 179 | U13: Yes | V13: Yes | W13: 2 | X13: 2.2
A14: BYJ1013 | B14: Onveer Walla | C14: 20 | D14: Male | E14: Ujjain | F14: West Bengal | G14: NEET Prep | H14: Hyderabad Hub | I14: May 2017 | J14: Retired | K14: 20+ | L14: Adult Learners | M14: NON PREMIUM LEARNER | N14: App Only | O14: 21724.55 | P14: 18.4 | Q14: 57752.06 | R14: Closed | S14: 411 | T14: 88 | U14: No | V14: Yes | W14: 5 | X14: 2.1
A15: BYJ1014 | B15: Ladli Madan | C15: 39 | D15: M | E15: Anantapur | F15: Gujarat | G15: NEET Prep | H15: Bengaluru South | I15: Sep 2020 | J15: Homemaker | K15: 20+ | L15: Adult Learners | M15: NON PREMIUM LEARNER | N15: App Only | O15: 32816.81 | P15: 33.4 | Q15: 44888.07 | R15: ACTIVE | S15: 715 | T15: 0 | U15: N | V15: Yes | W15: 5 | X15: 5.7
A16: BYJ1015 | B16: Veer Balay | C16: 19 | D16: female | E16: Rewa | F16: Telangana | G16: NEET Prep | H16: Bengaluru South | I16: 2019-11-10 | J16: Business | K16: 17-19 | L16: Teens | M16: Premium Learner | N16: Web Only | O16: 93634.73 | P16: 39.2 | Q16: 53168.21 | R16: none | S16: 693 | T16: 62 | U16: Yes | V16: Yes | W16: 2 | X16: 2
A17: BYJ1016 | B17: Dominic Kakar | C17: 9 | D17: Male | E17: Rajpur Sonarpur | F17: Rajasthan | G17: NEET Prep | H17: Ahmedabad Center | I17: Dec 2025 | J17: Government Employee | K17: Under 10 | L17: Kids | M17: NON PREMIUM LEARNER | N17: Web Only | O17: 70260.11 | P17: 68 | Q17: 16638.68 | R17: NIL | S17: 544 | T17: 19 | U17: no | V17: N | W17: 3 | X17: 8.1
A18: BYJ1017 | B18: Meghana Shanker | C18: 30 | D18: male | E18: Bilaspur | F18: West Bengal | G18: NEET Prep | H18: Jaipur Center | I18: 2023-07-02 | J18: Self-Employed | K18: 20+ | L18: Adult Learners | M18: NON PREMIUM LEARNER | N18: Both App & Web | O18: 7832.13 | P18: 48.2 | Q18: 28618.78 | R18: closed | S18: 699 | T18: 107 | U18: Yes | V18: Y | W18: 4 | X18: 4.6
A19: BYJ1018 | B19: Yatin Yohannan | C19: 31 | D19: Male | E19: Bhimavaram | F19: Kerala | G19: Coding | H19: Kolkata Main | I19: 2025 | J19: Salaried | K19: 20+ | L19: Adult Learners | M19: NON PREMIUM LEARNER | N19: Web Only | O19: 31350.71 | P19: 29.6 | Q19: 27281.96 | R19: closed | S19: 584 | T19: 107 | U19: No | V19: No | W19: 5 | X19: 0.9
A20: BYJ1019 | B20: Mohini Pathak | C20: 10 | D20: Male | E20: Durgapur | F20: Delhi | G20: Coding | H20: Lucknow Hub | I20: Apr 2018 | J20: Retired | K20: 10-13 | L20: Kids | M20: PREMIUM LEARNER | N20: Web Only | O20: 106422.42 | P20: 17.6 | Q20: 36434.85 | R20: None | S20: 467 | T20: 27 | U20: Y | V20: No | W20: 2 | X20: 1.1
A21: BYJ1020 | B21: Gavin Batta | C21: 12 | D21: FEMALE | E21: Jamnagar | F21: Kerala | G21: Coding | H21: Pune East | I21: 22-07-2024 | J21: Salaried | K21: 10-13 | L21: Kids | M21: NON PREMIUM LEARNER | N21: Web Only | O21: 124237.98 | P21: 77.1 | Q21: 38135.11 | R21: CLOSED | S21: 456 | T21: 187 | U21: No | V21: No | W21: 5 | X21: 2.8
A22: BYJ1021 | B22: Pahal Bhatt | C22: 11 | D22: Female | E22: Eluru | F22: Rajasthan | G22: Robotics | H22: Pune East | I22: 28-08-2016 | J22: Business | K22: 10-13 | L22: Kids | M22: NON PREMIUM LEARNER | N22: Web Only | O22: 54349.13 | P22: 57.6 | Q22: 16576.11 | R22: active | S22: 387 | T22: 104 | U22: no | V22: No | W22: 4 | X22: 7.2
A23: BYJ1022 | B23: Zayan Apte | C23: 21 | D23: FEMALE | E23: Jorhat | F23: Uttar Pradesh | G23: NEET Prep | H23: Kolkata Main | I23: Jun 2024 | J23: Homemaker | K23: 20+ | L23: Adult Learners | M23: NON PREMIUM LEARNER | N23: Both App & Web | O23: 32924.72 | P23: 45.2 | Q23: 45731.38 | R23: active | S23: 521 | T23: 70 | U23: No | V23: Y | W23: 2 | X23: 3.6
A24: BYJ1023 | B24: Harini Choudhury | C24: 14 | D24: Female | E24: Raebareli | F24: Uttar Pradesh | G24: JEE Prep | H24: Mumbai West | I24: 2023 | J24: Government Employee | K24: 14-16 | L24: Teens | M24: PREMIUM LEARNER | N24: Web Only | O24: 31732.73 | P24: 75.6 | Q24: 28663.75 | R24: Active | S24: 803 | T24: 161 | U24: yes | V24: Y | W24: 1 | X24: 8.9
A25: BYJ1024 | B25: Sudiksha Aggarwal | C25: 44 | D25: MALE | E25: Orai | F25: Rajasthan | G25: JEE Prep | H25: Lucknow Hub | I25: 2022 | J25: Government Employee | K25: 20+ | L25: Adult Learners | M25: Non Premium Learner | N25: App Only | O25: 95699.68 | P25: 11.1 | Q25: 14391.91 | R25: None | S25: N/A | T25: 115 | U25: N | V25: yes | W25: 3 | X25: 6.5
A26: BYJ1025 | B26: Yashica Cherian | C26: 20 | D26: FEMALE | E26: Guna | F26: Delhi | G26: Robotics | H26: Bengaluru South | I26: 2024-04-21 | J26: Homemaker | K26: 20+ | L26: Adult Learners | M26: Non Premium Learner | N26: App Only | O26: 119931.14 | P26: 66.8 | Q26: 55271.55 | R26: Closed | S26: 779 | T26: 179 | U26: N | V26: No | W26: 1 | X26: 5.6
A27: BYJ1026 | B27: Michael Prakash | C27: 44 | D27: Female | E27: Panvel | F27: Kerala | G27: Coding | H27: Hyderabad Hub | I27: 2025-01-25 | J27: Self-Employed | K27: 20+ | L27: Adult Learners | M27: NON PREMIUM LEARNER | N27: Web Only | O27: 31315.93 | P27: 52.6 | Q27: 29503.55 | R27: Active | S27: 656 | T27: 82 | U27: yes | V27: No | W27: 4 | X27: 2.9
A28: BYJ1027 | B28: Ekiya Suresh | C28: 41 | D28: Male | E28: Gorakhpur | F28: Telangana | G28: NEET Prep | H28: Bengaluru South | I28: 2022 | J28: Retired | K28: 20+ | L28: Adult Learners | M28: NON PREMIUM LEARNER | N28: App Only | O28: 32199.47 | P28: 61.7 | Q28: 37524.52 | R28: active | S28: 573 | T28: 73 | U28: No | V28: Yes | W28: 5 | X28: 7.3
A29: BYJ1028 | B29: Damyanti Khatri | C29: 6 | D29: Female | E29: New Delhi | F29: Karnataka | G29: Spoken English | H29: Bengaluru South | I29: 23-08-2018 | J29: Government Employee | K29: Under 10 | L29: Kids | M29: NON PREMIUM LEARNER | N29: Web Only | O29: 147135.47 | P29: 46.3 | Q29: 23015.16 | S29: 439 | T29: 70 | U29: N | V29: No | W29: 3 | X29: 6.7
A30: BYJ1029 | B30: Frederick Sunder | C30: 37 | D30: Male | E30: Katihar | F30: Gujarat | G30: NEET Prep | H30: Jaipur Center | I30: 15-07-2024 | J30: Business | K30: 20+ | L30: Adult Learners | M30: NON PREMIUM LEARNER | N30: Web Only | O30: 38866.55 | P30: 8.3 | Q30: 44682.31 | R30: NIL | S30: 695 | T30: 166 | U30: Yes | V30: yes | W30: 5 | X30: 8.7
A31: BYJ1030 | B31: Kabir Soman | C31: 34 | D31: MALE | E31: Bilaspur | F31: Tamil Nadu | G31: Science | H31: Kolkata Main | I31: 16-02-2018 | J31: Homemaker | K31: 20+ | L31: Adult Learners | M31: NON PREMIUM LEARNER | N31: App Only | O31: 128505.97 | P31: 69.5 | Q31: 22800.56 | R31: CLOSED | S31: 799 | T31: 9 | U31: yes | V31: no | W31: 1 | X31: 4.2
A32: BYJ1031 | B32: Siddharth Zacharia | C32: 12 | D32: female | E32: Bijapur | F32: Tamil Nadu | G32: Coding | H32: Pune East | I32: 12-05-2016 | J32: Self-Employed | K32: 10-13 | L32: Kids | M32: PREMIUM LEARNER | N32: Both App & Web | O32: 103861.05 | P32: 18.1 | Q32: 36569.51 | R32: CLOSED | S32: 546 | T32: 149 | U32: yes | V32: N | W32: 4 | X32: 2.7
A33: BYJ1032 | B33: Kashvi Sarma | C33: 24 | D33: Male | E33: Jamshedpur | F33: Gujarat | G33: JEE Prep | H33: Kolkata Main | I33: 28-08-2020 | J33: Business | K33: 20+ | L33: Adult Learners | M33: NON PREMIUM LEARNER | N33: App Only | O33: 39394.83 | P33: 48.1 | Q33: 59561.52 | R33: Closed | S33: 705 | T33: 144 | U33: Yes | V33: no | W33: 5 | X33: 7.3
A34: BYJ1033 | B34: Umang Bhatt | C34: 22 | D34: Male | E34: Jaipur | F34: Tamil Nadu | G34: JEE Prep | H34: Ahmedabad Center | I34: 2016-10-12 | J34: Salaried | K34: 20+ | L34: Adult Learners | M34: NON PREMIUM LEARNER | N34: Web Only | O34: 30467.81 | P34: 45.5 | Q34: 58289.37 | S34: 579 | T34: 65 | U34: N | V34: No | W34: 4 | X34: 8.7
A35: BYJ1034 | B35: Thomas Amble | C35: 31 | D35: Female | E35: Allahabad | F35: Tamil Nadu | G35: JEE Prep | H35: Jaipur Center | I35: 12-08-2017 | J35: Government Employee | K35: 20+ | L35: Adult Learners | M35: NON PREMIUM LEARNER | N35: Web Only | O35: 20710.18 | P35: 6.9 | Q35: 53054.09 | R35: NONE | S35: 526 | T35: 162 | U35: N | V35: No | W35: 2 | X35: 0.9
A36: BYJ1035 | B36: Ekansh Balay | C36: 13 | D36: male | E36: Madurai | F36: Maharashtra | G36: Robotics | H36: Ahmedabad Center | I36: Nov 2021 | J36: Government Employee | K36: 10-13 | L36: Kids | M36: NON PREMIUM LEARNER | N36: Web Only | O36: 99963.68 | P36: 51.2 | Q36: 56343.18 | R36: Closed | S36: 679 | T36: 113 | U36: Y | V36: Y | W36: 5 | X36: 8.2
A37: BYJ1036 | B37: Arya Sunder | C37: 23 | D37: Male | E37: Panvel | F37: Rajasthan | G37: Mathematics | H37: Delhi North | I37: 02-01-2025 | J37: Business | K37: 20+ | L37: Adult Learners | M37: NON PREMIUM LEARNER | N37: App Only | O37: 14948.47 | P37: 20.5 | Q37: 12957.08 | R37: ACTIVE | S37: 451 | T37: 152 | U37: Y | V37: yes | W37: 5 | X37: 2.6
A38: BYJ1037 | B38: Urvashi Kibe | C38: 7 | D38: Male | E38: Vellore | F38: Delhi | G38: NEET Prep | H38: Chennai Central | I38: 2018-05-02 | J38: Retired | K38: Under 10 | L38: Kids | M38: NON PREMIUM LEARNER | N38: App Only | O38: 74055.66 | P38: 43.5 | Q38: 6543.24 | R38: none | S38: 344 | T38: 168 | U38: No | V38: Yes | W38: 4 | X38: 7.7
A39: BYJ1038 | B39: Girindra Chatterjee | C39: 34 | D39: Male | E39: Raichur | F39: Maharashtra | G39: Mathematics | H39: Mumbai West | I39: 21-10-2020 | J39: Self-Employed | K39: 20+ | L39: Adult Learners | M39: NON PREMIUM LEARNER | N39: Web Only | O39: 78304.91 | P39: 64.5 | Q39: 6864.84 | S39: 520 | T39: 58 | U39: N | V39: No | W39: 4 | X39: 6.7
A40: BYJ1039 | B40: Nirja Sibal | C40: 22 | D40: female | E40: Navi Mumbai | F40: Rajasthan | G40: Mathematics | H40: Bengaluru South | I40: 2017 | J40: Retired | K40: 20+ | L40: Adult Learners | M40: NON PREMIUM LEARNER | N40: Both App & Web | O40: 13697.24 | P40: 47.1 | Q40: 40200.8 | R40: closed | S40: 733 | T40: 184 | U40: Y | V40: N | W40: 1 | X40: 5.4
...

Sheet formula
A1: BYJU'S Learning Analytics - Data Cleaning
A2: Cleaning area | B2: Formula used | C2: Purpose
A3: Standardize Text Values | B3: UPPER() | C3: Converts text into a consistent uppercase format.
A4: Remove Extra Spaces | B4: TRIM() | C4: Removes unnecessary spaces from text values.
A5: Remove Hidden Characters | B5: CLEAN() | C5: Removes non-printable characters.
A6: Handle Missing Values | B6: IF() | C6: Replaces blank or missing values with a suitable value.
A7: Identify Duplicates | B7: COUNTIF() | C7: Detects duplicate records in the dataset.
A8: Handle Errors | B8: IFERROR() | C8: Handles formula errors and returns a meaningful result.
A9: Convert Text to Number | B9: VALUE() | C9: Converts numbers stored as text into numeric values.
A10: Clean Currency Values | B10: SUBSTITUTE() + VALUE() | C10: Removes currency symbols and converts values into numbers.
A11: Validate Performance Score | B11: IF() + AND() | C11: Checks whether performance scores are within the valid range.
A12: Standardize Text | B12: PROPER() | C12: Converts text into consistent capitalization.
A13: Standardize Categories | B13: UPPER() | C13: Converts category values into a consistent uppercase format.
... A16: Extract Clean Text | B16: TEXTBEFORE() / TEXTAFTER() | C16: Extracts the required portion of text from a mixed-value cell.
A18: KPI METRICS
A19: KPI Metric | B19: Formula | C19: Purpose
A20: Total Students | B20: (=COUNTA(Student_ID_Range) | C20: Counts the total number of students.
A21: Total Fees Collected | B21: (=SUM(Fee_Paid_Clean_Range) | C21: Calculates the total fees collected.
A22: Fee Outstanding | B22: (=SUM(Fee_Outstanding_Range) | C22: Calculates the total outstanding fees.
A23: Average Performance Score | B23: (=AVERAGE(Performance_Score_Clean_Range) | C23: Calculates the average student performance score.
A26: ADDITIONAL METRICS
A27: Additional Metric | B27: Formula / Method | C27: Purpose
A28: Total Study Hours | B28: (=SUM(Study_Hours_Range)) | C28: Calculates the total study hours recorded by students.
A29: Average Study Hours | B29: (=AVERAGE(Study_Hours_Range)) | C29: Calculates the average study time per student.
A30: Student Count by Course | B30: (=COUNTIF(Course_Type_Range,Course_Name)) | C30: Counts students belonging to a specific course.
A31: Fee Collection by Course | B31: (=SUMIF(Course_Type_Range,Course_Name,Fee_Paid_Clean_Range)) | C31: Calculates fees collected for a particular course.
A32: Outstanding Fees by Course | B32: (=SUMIF(Course_Type_Range,Course_Name,Fee_Outstanding_Range)) | C32: Calculates pending fees for a particular course.
A33: Average Performance by Course | B33: (=AVERAGEIF(Course_Type_Range,Course_Name,Performance_Score_Clean_Range)) | C33: Calculates average performance for each course.
A34: Students by Learning Mode | B34: (=COUNTIF(Learning_Mode_Clean_Range,Mode_Name)) | C34: Counts students based on learning mode.
A35: Students by Learner Category | B35: (=COUNTIF(Learner_Category_Clean_Range,Category_Name)) | C35: Counts students in each learner category.
A36: Students by State | B36: (=COUNTIF(State_Range,State_Name)) | C36: Counts students from each state.
A37: Fee Collection Percentage | B37: (=Fee_Paid/(Fee_Paid+Fee_Outstanding)*100) | C37: Calculates the percentage of fees collected.
A38: Outstanding Fee Percentage | B38: (=Fee_Outstanding/(Fee_Paid+Fee_Outstanding)*100) | C38: Calculates the percentage of fees outstanding.
A39: Course-wise Performance Comparison | B39: (=AVERAGEIF()) | C39: Compares average performance across courses.

Sheet cleaned data
B2: DATA QUALITY ASSUMPTIONS (reference inputs used by cleaning formulas)
B4: Median Age (valid records only) | C4: 24 | D4: Age between 3 and 80 only; used to impute missing/invalid Age
B5: Valid Age - Minimum | C5: 3 | D5: Ages below this are treated as data-entry errors | U5: =ISNUMBER(U11) -> TRUE
B6: Valid Age - Maximum | C6: 80 | D6: Ages above this are treated as data-entry errors | T6: =ISNUMBER(H2) -> FALSE
B7: Median Fee Paid | C7: 71742.19 | D7: Used to impute blank Fee_Paid values
B8: Median Performance Score | C8: 596 | D8: Used to impute blank Performance_Score values
A10: Student_ID | B10: Name | C10: Age_Clean | D10: Age_Flag | E10: Gender_Clean | F10: City_Clean | G10: State_Clean | H10: Course_Type_Clean | I10: Learning_Center_Clean | J10: Enrollment_Year | K10: Parent_Occupation_Clean | L10: Age_Group_Calc | M10: Age_Category_Calc | N10: Learner_Category_Clean | O10: Learning_Mode_Clean | P10: Fee_Paid_Clean | Q10: Fee_Paid_Flag | R10: Avg_Monthly_Study_Hours | S10: Fee_Outstanding | T10: Subscription_Status_Clean | U10: Performance_Score_Clean | V10: Performance_Score_Flag | W10: Sessions_Attended | X10: App_Usage_Clean | Y10: Web_Usage_Clean | Z10: Satisfaction_Score | AA10: Learning_Tenure_Years | AB10: Duplicate_Flag | AC10: Row_Quality_Flag
A11: =Raw_Data!A2 -> BYJ1001 | B11: =Raw_Data!B2 -> Aryan Maharaj | C11: =IF(OR(Raw_Data!C2="",Raw_Data!C2<$C$5,Raw_Data!C2>$C$6),$C$4,Raw_Data!C2) -> 24 | D11: =IF(Raw_Data!C2="","Missing-Imputed",IF(OR(Raw_Data!C2<$C$5,Raw_Data!C2>$C$6),"Outlier-Imputed","Original")) -> Missing-Imputed | E11: =IF(OR(UPPER(TRIM(Raw_Data!D2))="M",UPPER(TRIM(Raw_Data!D2))="MALE"),"Male","Female") -> Female | F11: =PROPER(TRIM(Raw_Data!E2)) -> Rajahmundry | G11: =PROPER(TRIM(Raw_Data!F2)) -> Karnataka | H11: =PROPER(TRIM(Raw_Data!G2)) -> Mathematics | I11: =PROPER(TRIM(Raw_Data!H2)) -> Lucknow Hub | J11: =IF(LEN(TRIM(Raw_Data!I2))=4,VALUE(TRIM(Raw_Data!I2)),IF(ISNUMBER(IFERROR(VALUE(MID(TRIM(Raw_Data!I2),1,4)),"NA")),VALUE(MID(TRIM(Raw_Data!I2),1,4)),VALUE(RIGHT(TRIM(Raw_Data!I2),4)))) -> 2022 | K11: =PROPER(TRIM(Raw_Data!J2)) -> Business | L11: =IF(C11<10,"Under 10",IF(C11<=13,"10-13",IF(C11<=16,"14-16",IF(C11<=19,"17-19","20+")))) -> 20+ | M11: =IF(OR(L11="Under 10",L11="10-13"),"Kids",IF(OR(L11="14-16",L11="17-19"),"Teens","Adult Learners")) -> Adult Learners | N11: =IF(ISNUMBER(SEARCH("NON",UPPER(Raw_Data!M2))),"Non-Premium Learner","Premium Learner") -> Premium Learner | O11: =PROPER(TRIM(Raw_Data!N2)) -> Both App & Web | P11: =IF(Raw_Data!O2="",$C$7,Raw_Data!O2) -> 33831.46 | Q11: =IF(Raw_Data!O2="","Missing-Imputed","Original") -> Original | R11: =Raw_Data!P2 -> 45.9 | S11: =Raw_Data!Q2 -> 13226.44 | T11: =IF(Raw_Data!R2="","Unknown",IF(ISNUMBER(SEARCH("ACT",UPPER(Raw_Data!R2))),"Active",IF(ISNUMBER(SEARCH("CLOS",UPPER(Raw_Data!R2))),"Closed","None"))) -> None | U11: =IF(Raw_Data!S2="",$C$8,VALUE(Raw_Data!S2)) -> 306 | V11: =IF(Raw_Data!S2="","Missing-Imputed","Original") -> Original | W11: =Raw_Data!T2 -> 40 | X11: =IF(ISNUMBER(SEARCH("Y",UPPER(TRIM(Raw_Data!U2)))),"Yes","No") -> No | Y11: =IF(ISNUMBER(SEARCH("Y",UPPER(TRIM(Raw_Data!V2)))),"Yes","No") -> No | Z11: =Raw_Data!W2 -> 2 | AA11: =Raw_Data!X2 -> 8.6 | AB11: =IF(COUNTIFS(Raw_Data!$A$2:$A$616,Raw_Data!A2)>1,"Duplicate","Unique") -> Unique | AC11: =IF(AB11="Duplicate","Review-Duplicate",IF(OR(D11<>"Original",Q11<>"Original",V11<>"Original"),"Imputed","Clean")) -> Imputed
A12: =Raw_Data!A3 -> BYJ1002 | B12: =Raw_Data!B3 -> Harsh Chahal | C12: =IF(OR(Raw_Data!C3="",Raw_Data!C3<$C$5,Raw_Data!C3>$C$6),$C$4,Raw_Data!C3) -> 12 | D12: =IF(Raw_Data!C3="","Missing-Imputed",IF(OR(Raw_Data!C3<$C$5,Raw_Data!C3>$C$6),"Outlier-Imputed","Original")) -> Original | E12: =IF(OR(UPPER(TRIM(Raw_Data!D3))="M",UPPER(TRIM(Raw_Data!D3))="MALE"),"Male","Female") -> Female | F12: =PROPER(TRIM(Raw_Data!E3)) -> Patna | G12: =PROPER(TRIM(Raw_Data!F3)) -> Tamil Nadu | H12: =PROPER(TRIM(Raw_Data!G3)) -> Spoken English | I12: =PROPER(TRIM(Raw_Data!H3)) -> Jaipur Center | J12: =IF(LEN(TRIM(Raw_Data!I3))=4,VALUE(TRIM(Raw_Data!I3)),IF(ISNUMBER(IFERROR(VALUE(MID(TRIM(Raw_Data!I3),1,4)),"NA")),VALUE(MID(TRIM(Raw_Data!I3),1,4)),VALUE(RIGHT(TRIM(Raw_Data!I3),4)))) -> 2017 | K12: =PROPER(TRIM(Raw_Data!J3)) -> Retired | L12: =IF(C12<10,"Under 10",IF(C12<=13,"10-13",IF(C12<=16,"14-16",IF(C12<=19,"17-19","20+")))) -> 10-13 | M12: =IF(OR(L12="Under 10",L12="10-13"),"Kids",IF(OR(L12="14-16",L12="17-19"),"Teens","Adult Learners")) -> Kids | N12: =IF(ISNUMBER(SEARCH("NON",UPPER(Raw_Data!M3))),"Non-Premium Learner","Premium Learner") -> Non-Premium Learner | O12: =PROPER(TRIM(Raw_Data!N3)) -> Both App & Web | P12: =IF(Raw_Data!O3="",$C$7,Raw_Data!O3) -> 32881.85 | Q12: =IF(Raw_Data!O3="","Missing-Imputed","Original") -> Original | R12: =Raw_Data!P3 -> 54.6 | S12: =Raw_Data!Q3 -> 46384.1 | T12: =IF(Raw_Data!R3="","Unknown",IF(ISNUMBER(SEARCH("ACT",UPPER(Raw_Data!R3))),"Active",IF(ISNUMBER(SEARCH("CLOS",UPPER(Raw_Data!R3))),"Closed","None"))) -> Active | U12: =IF(Raw_Data!S3="",$C$8,VALUE(Raw_Data!S3)) -> 403 | V12: =IF(Raw_Data!S3="","Missing-Imputed","Original") -> Original | W12: =Raw_Data!T3 -> 116 | X12: =IF(ISNUMBER(SEARCH("Y",UPPER(TRIM(Raw_Data!U3)))),"Yes","No") -> No | Y12: =IF(ISNUMBER(SEARCH("Y",UPPER(TRIM(Raw_Data!V3)))),"Yes","No") -> No | Z12: =Raw_Data!W3 -> 2 | AA12: =Raw_Data!X3 -> 6.2 | AB12: =IF(COUNTIFS(Raw_Data!$A$2:$A$616,Raw_Data!A3)>1,"Duplicate","Unique") -> Unique | AC12: =IF(AB12="Duplicate","Review-Duplicate",IF(OR(D12<>"Original",Q12<>"Original",V12<>"Original"),"Imputed","Clean")) -> Clean
A13: =Raw_Data!A4 -> BYJ1003 | B13: =Raw_Data!B4 -> Girik Kamdar | C13: =IF(OR(Raw_Data!C4="",Raw_Data!C4<$C$5,Raw_Data!C4>$C$6),$C$4,Raw_Data!C4) -> 10 | D13: =IF(Raw_Data!C4="","Missing-Imputed",IF(OR(Raw_Data!C4<$C$5,Raw_Data!C4>$C$6),"Outlier-Imputed","Original")) -> Original | E13: =IF(OR(UPPER(TRIM(Raw_Data!D4))="M",UPPER(TRIM(Raw_Data!D4))="MALE"),"Male","Female") -> Male | F13: =PROPER(TRIM(Raw_Data!E4)) -> Dibrugarh | G13: =PROPER(TRIM(Raw_Data!F4)) -> Maharashtra | H13: =PROPER(TRIM(Raw_Data!G4)) -> Spoken English | I13: =PROPER(TRIM(Raw_Data!H4)) -> Kolkata Main | J13: =IF(LEN(TRIM(Raw_Data!I4))=4,VALUE(TRIM(Raw_Data!I4)),IF(ISNUMBER(IFERROR(VALUE(MID(TRIM(Raw_Data!I4),1,4)),"NA")),VALUE(MID(TRIM(Raw_Data!I4),1,4)),VALUE(RIGHT(TRIM(Raw_Data!I4),4)))) -> 2020 | K13: =PROPER(TRIM(Raw_Data!J4)) -> Retired | L13: =IF(C13<10,"Under 10",IF(C13<=13,"10-13",IF(C13<=16,"14-16",IF(C13<=19,"17-19","20+")))) -> 10-13 | M13: =IF(OR(L13="Under 10",L13="10-13"),"Kids",IF(OR(L13="14-16",L13="17-19"),"Teens","Adult Learners")) -> Kids | N13: =IF(ISNUMBER(SEARCH("NON",UPPER(Raw_Data!M4))),"Non-Premium Learner","Premium Learner") -> Non-Premium Learner | O13: =PROPER(TRIM(Raw_Data!N4)) -> App Only | P13: =IF(Raw_Data!O4="",$C$7,Raw_Data!O4) -> 38211.97 | Q13: =IF(Raw_Data!O4="","Missing-Imputed","Original") -> Original | R13: =Raw_Data!P4 -> 28.7 | S13: =Raw_Data!Q4 -> 16064.45 | T13: =IF(Raw_Data!R4="","Unknown",IF(ISNUMBER(SEARCH("ACT",UPPER(Raw_Data!R4))),"Active",IF(ISNUMBER(SEARCH("CLOS",UPPER(Raw_Data!R4))),"Closed","None"))) -> Active | U13: =IF(Raw_Data!S4="",$C$8,VALUE(Raw_Data!S4)) -> 517 | V13: =IF(Raw_Data!S4="","Missing-Imputed","Original") -> Original | W13: =Raw_Data!T4 -> 101 | X13: =IF(ISNUMBER(SEARCH("Y",UPPER(TRIM(Raw_Data!U4)))),"Yes","No") -> No | Y13: =IF(ISNUMBER(SEARCH("Y",UPPER(TRIM(Raw_Data!V4)))),"Yes","No") -> No | Z13: =Raw_Data!W4 -> 2 | AA13: =Raw_Data!X4 -> 6.8 | AB13: =IF(COUNTIFS(Raw_Data!$A$2:$A$616,Raw_Data!A4)>1,"Duplicate","Unique") -> Unique | AC13: =IF(AB13="Duplicate","Review-Duplicate",IF(OR(D13<>"Original",Q13<>"Original",V13<>"Original"),"Imputed","Clean")) -> Clean
A14: =Raw_Data!A5 -> BYJ1004 | B14: =Raw_Data!B5 -> Rushil Saini | C14: =IF(OR(Raw_Data!C5="",Raw_Data!C5<$C$5,Raw_Data!C5>$C$6),$C$4,Raw_Data!C5) -> 33 | D14: =IF(Raw_Data!C5="","Missing-Imputed",IF(OR(Raw_Data!C5<$C$5,Raw_Data!C5>$C$6),"Outlier-Imputed","Original")) -> Original | E14: =IF(OR(UPPER(TRIM(Raw_Data!D5))="M",UPPER(TRIM(Raw_Data!D5))="MALE"),"Male","Female") -> Female | F14: =PROPER(TRIM(Raw_Data!E5)) -> Sultan Pur Majra | G14: =PROPER(TRIM(Raw_Data!F5)) -> Maharashtra | H14: =PROPER(TRIM(Raw_Data!G5)) -> Spoken English | I14: =PROPER(TRIM(Raw_Data!H5)) -> Bengaluru South | J14: =IF(LEN(TRIM(Raw_Data!I5))=4,VALUE(TRIM(Raw_Data!I5)),IF(ISNUMBER(IFERROR(VALUE(MID(TRIM(Raw_Data!I5),1,4)),"NA")),VALUE(MID(TRIM(Raw_Data!I5),1,4)),VALUE(RIGHT(TRIM(Raw_Data!I5),4)))) -> 2016 | K14: =PROPER(TRIM(Raw_Data!J5)) -> Retired | L14: =IF(C14<10,"Under 10",IF(C14<=13,"10-13",IF(C14<=16,"14-16",IF(C14<=19,"17-19","20+")))) -> 20+ | M14: =IF(OR(L14="Under 10",L14="10-13"),"Kids",IF(OR(L14="14-16",L14="17-19"),"Teens","Adult Learners")) -> Adult Learners | N14: =IF(ISNUMBER(SEARCH("NON",UPPER(Raw_Data!M5))),"Non-Premium Learner","Premium Learner") -> Non-Premium Learner | O14: =PROPER(TRIM(Raw_Data!N5)) -> Web Only | P14: =IF(Raw_Data!O5="",$C$7,Raw_Data!O5) -> 91403.82 | Q14: =IF(Raw_Data!O5="","Missing-Imputed","Original") -> Original | R14: =Raw_Data!P5 -> 23.9 | S14: =Raw_Data!Q5 -> 33193.55 | T14: =IF(Raw_Data!R5="","Unknown",IF(ISNUMBER(SEARCH("ACT",UPPER(Raw_Data!R5))),"Active",IF(ISNUMBER(SEARCH("CLOS",UPPER(Raw_Data!R5))),"Closed","None"))) -> Active | U14: =IF(Raw_Data!S5="",$C$8,VALUE(Raw_Data!S5)) -> 849 | V14: =IF(Raw_Data!S5="","Missing-Imputed","Original") -> Original | W14: =Raw_Data!T5 -> 196 | X14: =IF(ISNUMBER(SEARCH("Y",UPPER(TRIM(Raw_Data!U5)))),"Yes","No") -> No | Y14: =IF(ISNUMBER(SEARCH("Y",UPPER(TRIM(Raw_Data!V5)))),"Yes","No") -> No | Z14: =Raw_Data!W5 -> 2 | AA14: =Raw_Data!X5 -> 4.4 | AB14: =IF(COUNTIFS(Raw_Data!$A$2:$A$616,Raw_Data!A5)>1,"Duplicate","Unique") -> Unique | AC14: =IF(AB14="Duplicate","Review-Duplicate",IF(OR(D14<>"Original",Q14<>"Original",V14<>"Original"),"Imputed","Clean")) -> Clean
A15: =Raw_Data!A6 -> BYJ1005 | B15: =Raw_Data!B6 -> Abeer Dutta | C15: =IF(OR(Raw_Data!C6="",Raw_Data!C6<$C$5,Raw_Data!C6>$C$6),$C$4,Raw_Data!C6) -> 22 | D15: =IF(Raw_Data!C6="","Missing-Imputed",IF(OR(Raw_Data!C6<$C$5,Raw_Data!C6>$C$6),"Outlier-Imputed","Original")) -> Original | E15: =IF(OR(UPPER(TRIM(Raw_Data!D6))="M",UPPER(TRIM(Raw_Data!D6))="MALE"),"Male","Female") -> Male | F15: =PROPER(TRIM(Raw_Data!E6)) -> Mau | G15: =PROPER(TRIM(Raw_Data!F6)) -> Telangana | H15: =PROPER(TRIM(Raw_Data!G6)) -> English | I15: =PROPER(TRIM(Raw_Data!H6)) -> Mumbai West | J15: =IF(LEN(TRIM(Raw_Data!I6))=4,VALUE(TRIM(Raw_Data!I6)),IF(ISNUMBER(IFERROR(VALUE(MID(TRIM(Raw_Data!I6),1,4)),"NA")),VALUE(MID(TRIM(Raw_Data!I6),1,4)),VALUE(RIGHT(TRIM(Raw_Data!I6),4)))) -> 2021 | K15: =PROPER(TRIM(Raw_Data!J6)) -> Government Employee | L15: =IF(C15<10,"Under 10",IF(C15<=13,"10-13",IF(C15<=16,"14-16",IF(C15<=19,"17-19","20+")))) -> 20+ | M15: =IF(OR(L15="Under 10",L15="10-13"),"Kids",IF(OR(L15="14-16",L15="17-19"),"Teens","Adult Learners")) -> Adult Learners | N15: =IF(ISNUMBER(SEARCH("NON",UPPER(Raw_Data!M6))),"Non-Premium Learner","Premium Learner") -> Non-Premium Learner | O15: =PROPER(TRIM(Raw_Data!N6)) -> Web Only | P15: =IF(Raw_Data!O6="",$C$7,Raw_Data!O6) -> 132414.67 | Q15: =IF(Raw_Data!O6="","Missing-Imputed","Original") -> Original | R15: =Raw_Data!P6 -> 28.1 | S15: =Raw_Data!Q6 -> 3475.51 | T15: =IF(Raw_Data!R6="","Unknown",IF(ISNUMBER(SEARCH("ACT",UPPER(Raw_Data!R6))),"Active",IF(ISNUMBER(SEARCH("CLOS",UPPER(Raw_Data!R6))),"Closed","None"))) -> None | U15: =IF(Raw_Data!S6="",$C$8,VALUE(Raw_Data!S6)) -> 387 | V15: =IF(Raw_Data!S6="","Missing-Imputed","Original") -> Original | W15: =Raw_Data!T6 -> 17 | X15: =IF(ISNUMBER(SEARCH("Y",UPPER(TRIM(Raw_Data!U6)))),"Yes","No") -> Yes | Y15: =IF(ISNUMBER(SEARCH("Y",UPPER(TRIM(Raw_Data!V6)))),"Yes","No") -> No | Z15: =Raw_Data!W6 -> 3 | AA15: =Raw_Data!X6 -> 5 | AB15: =IF(COUNTIFS(Raw_Data!$A$2:$A$616,Raw_Data!A6)>1,"Duplicate","Unique") -> Unique | AC15: =IF(AB15="Duplicate","Review-Duplicate",IF(OR(D15<>"Original",Q15<>"Original",V15<>"Original"),"Imputed","Clean")) -> Clean
A16: =Raw_Data!A7 -> BYJ1006 | B16: =Raw_Data!B7 -> Nachiket Kale | C16: =IF(OR(Raw_Data!C7="",Raw_Data!C7<$C$5,Raw_Data!C7>$C$6),$C$4,Raw_Data!C7) -> 40 | D16: =IF(Raw_Data!C7="","Missing-Imputed",IF(OR(Raw_Data!C7<$C$5,Raw_Data!C7>$C$6),"Outlier-Imputed","Original")) -> Original | E16: =IF(OR(UPPER(TRIM(Raw_Data!D7))="M",UPPER(TRIM(Raw_Data!D7))="MALE"),"Male","Female") -> Male | F16: =PROPER(TRIM(Raw_Data!E7)) -> Kota | G16: =PROPER(TRIM(Raw_Data!F7)) -> Gujarat | H16: =PROPER(TRIM(Raw_Data!G7)) -> Spoken English | I16: =PROPER(TRIM(Raw_Data!H7)) -> Jaipur Center | J16: =IF(LEN(TRIM(Raw_Data!I7))=4,VALUE(TRIM(Raw_Data!I7)),IF(ISNUMBER(IFERROR(VALUE(MID(TRIM(Raw_Data!I7),1,4)),"NA")),VALUE(MID(TRIM(Raw_Data!I7),1,4)),VALUE(RIGHT(TRIM(Raw_Data!I7),4)))) -> 2023 | K16: =PROPER(TRIM(Raw_Data!J7)) -> Salaried | L16: =IF(C16<10,"Under 10",IF(C16<=13,"10-13",IF(C16<=16,"14-16",IF(C16<=19,"17-19","20+")))) -> 20+ | M16: =IF(OR(L16="Under 10",L16="10-13"),"Kids",IF(OR(L16="14-16",L16="17-19"),"Teens","Adult Learners")) -> Adult Learners | N16: =IF(ISNUMBER(SEARCH("NON",UPPER(Raw_Data!M7))),"Non-Premium Learner","Premium Learner") -> Non-Premium Learner | O16: =PROPER(TRIM(Raw_Data!N7)) -> App Only | P16: =IF(Raw_Data!O7="",$C$7,Raw_Data!O7) -> 71742.19 | Q16: =IF(Raw_Data!O7="","Missing-Imputed","Original") -> Missing-Imputed | R16: =Raw_Data!P7 -> 58.1 | S16: =Raw_Data!Q7 -> 3532.43 | T16: =IF(Raw_Data!R7="","Unknown",IF(ISNUMBER(SEARCH("ACT",UPPER(Raw_Data!R7))),"Active",IF(ISNUMBER(SEARCH("CLOS",UPPER(Raw_Data!R7))),"Closed","None"))) -> Active | U16: =IF(Raw_Data!S7="",$C$8,VALUE(Raw_Data!S7)) -> 638 | V16: =IF(Raw_Data!S7="","Missing-Imputed","Original") -> Original | W16: =Raw_Data!T7 -> 60 | X16: =IF(ISNUMBER(SEARCH("Y",UPPER(TRIM(Raw_Data!U7)))),"Yes","No") -> No | Y16: =IF(ISNUMBER(SEARCH("Y",UPPER(TRIM(Raw_Data!V7)))),"Yes","No") -> Yes | Z16: =Raw_Data!W7 -> 5 | AA16: =Raw_Data!X7 -> 5.4 | AB16: =IF(COUNTIFS(Raw_Data!$A$2:$A$616,Raw_Data!A7)>1,"Duplicate","Unique") -> Unique | AC16: =IF(AB16="Duplicate","Review-Duplicate",IF(OR(D16<>"Original",Q16<>"Original",V16<>"Original"),"Imputed","Clean")) -> Imputed
A17: =Raw_Data!A8 -> BYJ1007 | B17: =Raw_Data!B8 -> Lajita Chatterjee | C17: =IF(OR(Raw_Data!C8="",Raw_Data!C8<$C$5,Raw_Data!C8>$C$6),$C$4,Raw_Data!C8) -> 32 | D17: =IF(Raw_Data!C8="","Missing-Imputed",IF(OR(Raw_Data!C8<$C$5,Raw_Data!C8>$C$6),"Outlier-Imputed","Original")) -> Original | E17: =IF(OR(UPPER(TRIM(Raw_Data!D8))="M",UPPER(TRIM(Raw_Data!D8))="MALE"),"Male","Female") -> Male | F17: =PROPER(TRIM(Raw_Data!E8)) -> Hapur | G17: =PROPER(TRIM(Raw_Data!F8)) -> West Bengal | H17: =PROPER(TRIM(Raw_Data!G8)) -> Neet Prep | I17: =PROPER(TRIM(Raw_Data!H8)) -> Kolkata Main | J17: =IF(LEN(TRIM(Raw_Data!I8))=4,VALUE(TRIM(Raw_Data!I8)),IF(ISNUMBER(IFERROR(VALUE(MID(TRIM(Raw_Data!I8),1,4)),"NA")),VALUE(MID(TRIM(Raw_Data!I8),1,4)),VALUE(RIGHT(TRIM(Raw_Data!I8),4)))) -> 2022 | K17: =PROPER(TRIM(Raw_Data!J8)) -> Retired | L17: =IF(C17<10,"Under 10",IF(C17<=13,"10-13",IF(C17<=16,"14-16",IF(C17<=19,"17-19","20+")))) -> 20+ | M17: =IF(OR(L17="Under 10",L17="10-13"),"Kids",IF(OR(L17="14-16",L17="17-19"),"Teens","Adult Learners")) -> Adult Learners | N17: =IF(ISNUMBER(SEARCH("NON",UPPER(Raw_Data!M8))),"Non-Premium Learner","Premium Learner") -> Non-Premium Learner | O17: =PROPER(TRIM(Raw_Data!N8)) -> App Only | P17: =IF(Raw_Data!O8="",$C$7,Raw_Data!O8) -> 63380.09 | Q17: =IF(Raw_Data!O8="","Missing-Imputed","Original") -> Original | R17: =Raw_Data!P8 -> 69.6 | S17: =Raw_Data!Q8 -> 14919.38 | T17: =IF(Raw_Data!R8="","Unknown",IF(ISNUMBER(SEARCH("ACT",UPPER(Raw_Data!R8))),"Active",IF(ISNUMBER(SEARCH("CLOS",UPPER(Raw_Data!R8))),"Closed","None"))) -> Active | U17: =IF(Raw_Data!S8="",$C$8,VALUE(Raw_Data!S8)) -> 443 | V17: =IF(Raw_Data!S8="","Missing-Imputed","Original") -> Original | W17: =Raw_Data!T8 -> 71 | X17: =IF(ISNUMBER(SEARCH("Y",UPPER(TRIM(Raw_Data!U8)))),"Yes","No") -> No | Y17: =IF(ISNUMBER(SEARCH("Y",UPPER(TRIM(Raw_Data!V8)))),"Yes","No") -> Yes | Z17: =Raw_Data!W8 -> 5 | AA17: =Raw_Data!X8 -> 1.3 | AB17: =IF(COUNTIFS(Raw_Data!$A$2:$A$616,Raw_Data!A8)>1,"Duplicate","Unique") -> Unique | AC17: =IF(AB17="Duplicate","Review-Duplicate",IF(OR(D17<>"Original",Q17<>"Original",V17<>"Original"),"Imputed","Clean")) -> Clean
A18: =Raw_Data!A9 -> BYJ1008 | B18: =Raw_Data!B9 -> Caleb Sharaf | C18: =IF(OR(Raw_Data!C9="",Raw_Data!C9<$C$5,Raw_Data!C9>$C$6),$C$4,Raw_Data!C9) -> 6 | D18: =IF(Raw_Data!C9="","Missing-Imputed",IF(OR(Raw_Data!C9<$C$5,Raw_Data!C9>$C$6),"Outlier-Imputed","Original")) -> Original | E18: =IF(OR(UPPER(TRIM(Raw_Data!D9))="M",UPPER(TRIM(Raw_Data!D9))="MALE"),"Male","Female") -> Male | F18: =PROPER(TRIM(Raw_Data!E9)) -> Burhanpur | G18: =PROPER(TRIM(Raw_Data!F9)) -> Rajasthan | H18: =PROPER(TRIM(Raw_Data!G9)) -> Spoken English | I18: =PROPER(TRIM(Raw_Data!H9)) -> Delhi North | J18: =IF(LEN(TRIM(Raw_Data!I9))=4,VALUE(TRIM(Raw_Data!I9)),IF(ISNUMBER(IFERROR(VALUE(MID(TRIM(Raw_Data!I9),1,4)),"NA")),VALUE(MID(TRIM(Raw_Data!I9),1,4)),VALUE(RIGHT(TRIM(Raw_Data!I9),4)))) -> 2022 | K18: =PROPER(TRIM(Raw_Data!J9)) -> Salaried | L18: =IF(C18<10,"Under 10",IF(C18<=13,"10-13",IF(C18<=16,"14-16",IF(C18<=19,"17-19","20+")))) -> Under 10 | M18: =IF(OR(L18="Under 10",L18="10-13"),"Kids",IF(OR(L18="14-16",L18="17-19"),"Teens","Adult Learners")) -> Kids | N18: =IF(ISNUMBER(SEARCH("NON",UPPER(Raw_Data!M9))),"Non-Premium Learner","Premium Learner") -> Non-Premium Learner | O18: =PROPER(TRIM(Raw_Data!N9)) -> Web Only | P18: =IF(Raw_Data!O9="",$C$7,Raw_Data!O9) -> 46361.14 | Q18: =IF(Raw_Data!O9="","Missing-Imputed","Original") -> Original | R18: =Raw_Data!P9 -> 59.8 | S18: =Raw_Data!Q9 -> 47001.69 | T18: =IF(Raw_Data!R9="","Unknown",IF(ISNUMBER(SEARCH("ACT",UPPER(Raw_Data!R9))),"Active",IF(ISNUMBER(SEARCH("CLOS",UPPER(Raw_Data!R9))),"Closed","None"))) -> None | U18: =IF(Raw_Data!S9="",$C$8,VALUE(Raw_Data!S9)) -> 458 | V18: =IF(Raw_Data!S9="","Missing-Imputed","Original") -> Original | W18: =Raw_Data!T9 -> 55 | X18: =IF(ISNUMBER(SEARCH("Y",UPPER(TRIM(Raw_Data!U9)))),"Yes","No") -> Yes | Y18: =IF(ISNUMBER(SEARCH("Y",UPPER(TRIM(Raw_Data!V9)))),"Yes","No") -> No | Z18: =Raw_Data!W9 -> 1 | AA18: =Raw_Data!X9 -> 5.5 | AB18: =IF(COUNTIFS(Raw_Data!$A$2:$A$616,Raw_Data!A9)>1,"Duplicate","Unique") -> Unique | AC18: =IF(AB18="Duplicate","Review-Duplicate",IF(OR(D18<>"Original",Q18<>"Original",V18<>"Original"),"Imputed","Clean")) -> Clean
A19: =Raw_Data!A10 -> BYJ1009 | B19: =Raw_Data!B10 -> Chaaya Pathak | C19: =IF(OR(Raw_Data!C10="",Raw_Data!C10<$C$5,Raw_Data!C10>$C$6),$C$4,Raw_Data!C10) -> 16 | D19: =IF(Raw_Data!C10="","Missing-Imputed",IF(OR(Raw_Data!C10<$C$5,Raw_Data!C10>$C$6),"Outlier-Imputed","Original")) -> Original | E19: =IF(OR(UPPER(TRIM(Raw_Data!D10))="M",UPPER(TRIM(Raw_Data!D10))="MALE"),"Male","Female") -> Male | F19: =PROPER(TRIM(Raw_Data!E10)) -> Coimbatore | G19: =PROPER(TRIM(Raw_Data!F10)) -> Maharashtra | H19: =PROPER(TRIM(Raw_Data!G10)) -> Mathematics | I19: =PROPER(TRIM(Raw_Data!H10)) -> Lucknow Hub | J19: =IF(LEN(TRIM(Raw_Data!I10))=4,VALUE(TRIM(Raw_Data!I10)),IF(ISNUMBER(IFERROR(VALUE(MID(TRIM(Raw_Data!I10),1,4)),"NA")),VALUE(MID(TRIM(Raw_Data!I10),1,4)),VALUE(RIGHT(TRIM(Raw_Data!I10),4)))) -> 2017 | K19: =PROPER(TRIM(Raw_Data!J10)) -> Self-Employed | L19: =IF(C19<10,"Under 10",IF(C19<=13,"10-13",IF(C19<=16,"14-16",IF(C19<=19,"17-19","20+")))) -> 14-16 | M19: =IF(OR(L19="Under 10",L19="10-13"),"Kids",IF(OR(L19="14-16",L19="17-19"),"Teens","Adult Learners")) -> Teens | N19: =IF(ISNUMBER(SEARCH("NON",UPPER(Raw_Data!M10))),"Non-Premium Learner","Premium Learner") -> Premium Learner | O19: =PROPER(TRIM(Raw_Data!N10)) -> App Only | P19: =IF(Raw_Data!O10="",$C$7,Raw_Data!O10) -> 88943.26 | Q19: =IF(Raw_Data!O10="","Missing-Imputed","Original") -> Original | R19: =Raw_Data!P10 -> 11.1 | S19: =Raw_Data!Q10 -> 39442.39 | T19: =IF(Raw_Data!R10="","Unknown",IF(ISNUMBER(SEARCH("ACT",UPPER(Raw_Data!R10))),"Active",IF(ISNUMBER(SEARCH("CLOS",UPPER(Raw_Data!R10))),"Closed","None"))) -> Unknown | U19: =IF(Raw_Data!S10="",$C$8,VALUE(Raw_Data!S10)) -> 623 | V19: =IF(Raw_Data!S10="","Missing-Imputed","Original") -> Original | W19: =Raw_Data!T10 -> 52 | X19: =IF(ISNUMBER(SEARCH("Y",UPPER(TRIM(Raw_Data!U10)))),"Yes","No") -> No | Y19: =IF(ISNUMBER(SEARCH("Y",UPPER(TRIM(Raw_Data!V10)))),"Yes","No") -> No | Z19: =Raw_Data!W10 -> 2 | AA19: =Raw_Data!X10 -> 6.2 | AB19: =IF(COUNTIFS(Raw_Data!$A$2:$A$616,Raw_Data!A10)>1,"Duplicate","Unique") -> Unique | AC19: =IF(AB19="Duplicate","Review-Duplicate",IF(OR(D19<>"Original",Q19<>"Original",V19<>"Original"),"Imputed","Clean")) -> Clean
A20: =Raw_Data!A11 -> BYJ1010 | B20: =Raw_Data!B11 -> Vedant Mann | C20: =IF(OR(Raw_Data!C11="",Raw_Data!C11<$C$5,Raw_Data!C11>$C$6),$C$4,Raw_Data!C11) -> 10 | D20: =IF(Raw_Data!C11="","Missing-Imputed",IF(OR(Raw_Data!C11<$C$5,Raw_Data!C11>$C$6),"Outlier-Imputed","Original")) -> Original | E20: =IF(OR(UPPER(TRIM(Raw_Data!D11))="M",UPPER(TRIM(Raw_Data!D11))="MALE"),"Male","Female") -> Male | F20: =PROPER(TRIM(Raw_Data!E11)) -> Muzaffarpur | G20: =PROPER(TRIM(Raw_Data!F11)) -> Kerala | H20: =PROPER(TRIM(Raw_Data!G11)) -> Mathematics | I20: =PROPER(TRIM(Raw_Data!H11)) -> Bengaluru South | J20: =IF(LEN(TRIM(Raw_Data!I11))=4,VALUE(TRIM(Raw_Data!I11)),IF(ISNUMBER(IFERROR(VALUE(MID(TRIM(Raw_Data!I11),1,4)),"NA")),VALUE(MID(TRIM(Raw_Data!I11),1,4)),VALUE(RIGHT(TRIM(Raw_Data!I11),4)))) -> 2024 | K20: =PROPER(TRIM(Raw_Data!J11)) -> Business | L20: =IF(C20<10,"Under 10",IF(C20<=13,"10-13",IF(C20<=16,"14-16",IF(C20<=19,"17-19","20+")))) -> 10-13 | M20: =IF(OR(L20="Under 10",L20="10-13"),"Kids",IF(OR(L20="14-16",L20="17-19"),"Teens","Adult Learners")) -> Kids | N20: =IF(ISNUMBER(SEARCH("NON",UPPER(Raw_Data!M11))),"Non-Premium Learner","Premium Learner") -> Non-Premium Learner | O20: =PROPER(TRIM(Raw_Data!N11)) -> App Only | P20: =IF(Raw_Data!O11="",$C$7,Raw_Data!O11) -> 58581.43 | Q20: =IF(Raw_Data!O11="","Missing-Imputed","Original") -> Original | R20: =Raw_Data!P11 -> 67.5 | S20: =Raw_Data!Q11 -> 42212.4 | T20: =IF(Raw_Data!R11="","Unknown",IF(ISNUMBER(SEARCH("ACT",UPPER(Raw_Data!R11))),"Active",IF(ISNUMBER(SEARCH("CLOS",UPPER(Raw_Data!R11))),"Closed","None"))) -> Unknown | U20: =IF(Raw_Data!S11="",$C$8,VALUE(Raw_Data!S11)) -> 308 | V20: =IF(Raw_Data!S11="","Missing-Imputed","Original") -> Original | W20: =Raw_Data!T11 -> 141 | X20: =IF(ISNUMBER(SEARCH("Y",UPPER(TRIM(Raw_Data!U11)))),"Yes","No") -> No | Y20: =IF(ISNUMBER(SEARCH("Y",UPPER(TRIM(Raw_Data!V11)))),"Yes","No") -> Yes | Z20: =Raw_Data!W11 -> 1 | AA20: =Raw_Data!X11 -> 8.1 | AB20: =IF(COUNTIFS(Raw_Data!$A$2:$A$616,Raw_Data!A11)>1,"Duplicate","Unique") -> Duplicate | AC20: =IF(AB20="Duplicate","Review-Duplicate",IF(OR(D20<>"Original",Q20<>"Original",V20<>"Original"),"Imputed","Clean")) -> Review-Duplicate
A21: =Raw_Data!A12 -> BYJ1011 | B21: =Raw_Data!B12 -> Lajita Mall | C21: =IF(OR(Raw_Data!C12="",Raw_Data!C12<$C$5,Raw_Data!C12>$C$6),$C$4,Raw_Data!C12) -> 24 | D21: =IF(Raw_Data!C12="","Missing-Imputed",IF(OR(Raw_Data!C12<$C$5,Raw_Data!C12>$C$6),"Outlier-Imputed","Original")) -> Original | E21: =IF(OR(UPPER(TRIM(Raw_Data!D12))="M",UPPER(TRIM(Raw_Data!D12))="MALE"),"Male","Female") -> Male | F21: =PROPER(TRIM(Raw_Data!E12)) -> Bharatpur | G21: =PROPER(TRIM(Raw_Data!F12)) -> Telangana | H21: =PROPER(TRIM(Raw_Data!G12)) -> Spoken English | I21: =PROPER(TRIM(Raw_Data!H12)) -> Hyderabad Hub | J21: =IF(LEN(TRIM(Raw_Data!I12))=4,VALUE(TRIM(Raw_Data!I12)),IF(ISNUMBER(IFERROR(VALUE(MID(TRIM(Raw_Data!I12),1,4)),"NA")),VALUE(MID(TRIM(Raw_Data!I12),1,4)),VALUE(RIGHT(TRIM(Raw_Data!I12),4)))) -> 2016 | K21: =PROPER(TRIM(Raw_Data!J12)) -> Homemaker | L21: =IF(C21<10,"Under 10",IF(C21<=13,"10-13",IF(C21<=16,"14-16",IF(C21<=19,"17-19","20+")))) -> 20+ | M21: =IF(OR(L21="Under 10",L21="10-13"),"Kids",IF(OR(L21="14-16",L21="17-19"),"Teens","Adult Learners")) -> Adult Learners | N21: =IF(ISNUMBER(SEARCH("NON",UPPER(Raw_Data!M12))),"Non-Premium Learner","Premium Learner") -> Premium Learner | O21: =PROPER(TRIM(Raw_Data!N12)) -> App Only | P21: =IF(Raw_Data!O12="",$C$7,Raw_Data!O12) -> 97381.44 | Q21: =IF(Raw_Data!O12="","Missing-Imputed","Original") -> Original | R21: =Raw_Data!P12 -> 60.6 | S21: =Raw_Data!Q12 -> 33100.83 | T21: =IF(Raw_Data!R12="","Unknown",IF(ISNUMBER(SEARCH("ACT",UPPER(Raw_Data!R12))),"Active",IF(ISNUMBER(SEARCH("CLOS",UPPER(Raw_Data!R12))),"Closed","None"))) -> Closed | U21: =IF(Raw_Data!S12="",$C$8,VALUE(Raw_Data!S12)) -> 309 | V21: =IF(Raw_Data!S12="","Missing-Imputed","Original") -> Original | W21: =Raw_Data!T12 -> 176 | X21: =IF(ISNUMBER(SEARCH("Y",UPPER(TRIM(Raw_Data!U12)))),"Yes","No") -> Yes | Y21: =IF(ISNUMBER(SEARCH("Y",UPPER(TRIM(Raw_Data!V12)))),"Yes","No") -> No | Z21: =Raw_Data!W12 -> 4 | AA21: =Raw_Data!X12 -> 1.6 | AB21: =IF(COUNTIFS(Raw_Data!$A$2:$A$616,Raw_Data!A12)>1,"Duplicate","Unique") -> Unique | AC21: =IF(AB21="Duplicate","Review-Duplicate",IF(OR(D21<>"Original",Q21<>"Original",V21<>"Original"),"Imputed","Clean")) -> Clean
A22: =Raw_Data!A13 -> BYJ1012 | B22: =Raw_Data!B13 -> Kamala Pant | C22: =IF(OR(Raw_Data!C13="",Raw_Data!C13<$C$5,Raw_Data!C13>$C$6),$C$4,Raw_Data!C13) -> 8 | D22: =IF(Raw_Data!C13="","Missing-Imputed",IF(OR(Raw_Data!C13<$C$5,Raw_Data!C13>$C$6),"Outlier-Imputed","Original")) -> Original | E22: =IF(OR(UPPER(TRIM(Raw_Data!D13))="M",UPPER(TRIM(Raw_Data!D13))="MALE"),"Male","Female") -> Female | F22: =PROPER(TRIM(Raw_Data!E13)) -> Shimoga | G22: =PROPER(TRIM(Raw_Data!F13)) -> Karnataka | H22: =PROPER(TRIM(Raw_Data!G13)) -> Neet Prep | I22: =PROPER(TRIM(Raw_Data!H13)) -> Jaipur Center | J22: =IF(LEN(TRIM(Raw_Data!I13))=4,VALUE(TRIM(Raw_Data!I13)),IF(ISNUMBER(IFERROR(VALUE(MID(TRIM(Raw_Data!I13),1,4)),"NA")),VALUE(MID(TRIM(Raw_Data!I13),1,4)),VALUE(RIGHT(TRIM(Raw_Data!I13),4)))) -> 2022 | K22: =PROPER(TRIM(Raw_Data!J13)) -> Business | L22: =IF(C22<10,"Under 10",IF(C22<=13,"10-13",IF(C22<=16,"14-16",IF(C22<=19,"17-19","20+")))) -> Under 10 | M22: =IF(OR(L22="Under 10",L22="10-13"),"Kids",IF(OR(L22="14-16",L22="17-19"),"Teens","Adult Learners")) -> Kids | N22: =IF(ISNUMBER(SEARCH("NON",UPPER(Raw_Data!M13))),"Non-Premium Learner","Premium Learner") -> Non-Premium Learner | O22: =PROPER(TRIM(Raw_Data!N13)) -> App Only | P22: =IF(Raw_Data!O13="",$C$7,Raw_Data!O13) -> 132805.35 | Q22: =IF(Raw_Data!O13="","Missing-Imputed","Original") -> Original | R22: =Raw_Data!P13 -> 60.2 | S22: =Raw_Data!Q13 -> 19931.13 | T22: =IF(Raw_Data!R13="","Unknown",IF(ISNUMBER(SEARCH("ACT",UPPER(Raw_Data!R13))),"Active",IF(ISNUMBER(SEARCH("CLOS",UPPER(Raw_Data!R13))),"Closed","None"))) -> Closed | U22: =IF(Raw_Data!S13="",$C$8,VALUE(Raw_Data!S13)) -> 554 | V22: =IF(Raw_Data!S13="","Missing-Imputed","Original") -> Original | W22: =Raw_Data!T13 -> 179 | X22: =IF(ISNUMBER(SEARCH("Y",UPPER(TRIM(Raw_Data!U13)))),"Yes","No") -> Yes | Y22: =IF(ISNUMBER(SEARCH("Y",UPPER(TRIM(Raw_Data!V13)))),"Yes","No") -> Yes | Z22: =Raw_Data!W13 -> 2 | AA22: =Raw_Data!X13 -> 2.2 | AB22: =IF(COUNTIFS(Raw_Data!$A$2:$A$616,Raw_Data!A13)>1,"Duplicate","Unique") -> Unique | AC22: =IF(AB22="Duplicate","Review-Duplicate",IF(OR(D22<>"Original",Q22<>"Original",V22<>"Original"),"Imputed","Clean")) -> Clean
... A596: =Raw_Data!A587 -> BYJ1586 | B596: =Raw_Data!B587 -> Ati Chander | C596: =IF(OR(Raw_Data!C587="",Raw_Data!C587<$C$5,Raw_Data!C587>$C$6),$C$4,Raw_Data!C587) -> 25 | D596: =IF(Raw_Data!C587="","Missing-Imputed",IF(OR(Raw_Data!C587<$C$5,Raw_Data!C587>$C$6),"Outlier-Imputed","Original")) -> Original | E596: =IF(OR(UPPER(TRIM(Raw_Data!D587))="M",UPPER(TRIM(Raw_Data!D587))="MALE"),"Male","Female") -> Male | F596: =PROPER(TRIM(Raw_Data!E587)) -> Ahmednagar | G596: =PROPER(TRIM(Raw_Data!F587)) -> Karnataka | H596: =PROPER(TRIM(Raw_Data!G587)) -> Mathematics | I596: =PROPER(TRIM(Raw_Data!H587)) -> Kolkata Main | J596: =IF(LEN(TRIM(Raw_Data!I587))=4,VALUE(TRIM(Raw_Data!I587)),IF(ISNUMBER(IFERROR(VALUE(MID(TRIM(Raw_Data!I587),1,4)),"NA")),VALUE(MID(TRIM(Raw_Data!I587),1,4)),VALUE(RIGHT(TRIM(Raw_Data!I587),4)))) -> 2023 | K596: =PROPER(TRIM(Raw_Data!J587)) -> Government Employee | L596: =IF(C596<10,"Under 10",IF(C596<=13,"10-13",IF(C596<=16,"14-16",IF(C596<=19,"17-19","20+")))) -> 20+ | M596: =IF(OR(L596="Under 10",L596="10-13"),"Kids",IF(OR(L596="14-16",L596="17-19"),"Teens","Adult Learners")) -> Adult Learners | N596: =IF(ISNUMBER(SEARCH("NON",UPPER(Raw_Data!M587))),"Non-Premium Learner","Premium Learner") -> Non-Premium Learner | O596: =PROPER(TRIM(Raw_Data!N587)) -> Web Only | P596: =IF(Raw_Data!O587="",$C$7,Raw_Data!O587) -> 148390.29 | Q596: =IF(Raw_Data!O587="","Missing-Imputed","Original") -> Original | R596: =Raw_Data!P587 -> 24.1 | S596: =Raw_Data!Q587 -> 40201.56 | T596: =IF(Raw_Data!R587="","Unknown",IF(ISNUMBER(SEARCH("ACT",UPPER(Raw_Data!R587))),"Active",IF(ISNUMBER(SEARCH("CLOS",UPPER(Raw_Data!R587))),"Closed","None"))) -> Closed | U596: =IF(Raw_Data!S587="",$C$8,VALUE(Raw_Data!S587)) -> 568 | V596: =IF(Raw_Data!S587="","Missing-Imputed","Original") -> Original | W596: =Raw_Data!T587 -> 136 | X596: =IF(ISNUMBER(SEARCH("Y",UPPER(TRIM(Raw_Data!U587)))),"Yes","No") -> Yes | Y596: =IF(ISNUMBER(SEARCH("Y",UPPER(TRIM(Raw_Data!V587)))),"Yes","No") -> Yes | Z596: =Raw_Data!W587 -> 5 | AA596: =Raw_Data!X587 -> 5.8 | AB596: =IF(COUNTIFS(Raw_Data!$A$2:$A$616,Raw_Data!A587)>1,"Duplicate","Unique") -> Unique | AC596: =IF(AB596="Duplicate","Review-Duplicate",IF(OR(D596<>"Original",Q596<>"Original",V596<>"Original"),"Imputed","Clean")) -> Clean
A597: =Raw_Data!A588 -> BYJ1587 | B597: =Raw_Data!B588 -> Kashish Shanker | C597: =IF(OR(Raw_Data!C588="",Raw_Data!C588<$C$5,Raw_Data!C588>$C$6),$C$4,Raw_Data!C588) -> 12 | D597: =IF(Raw_Data!C588="","Missing-Imputed",IF(OR(Raw_Data!C588<$C$5,Raw_Data!C588>$C$6),"Outlier-Imputed","Original")) -> Original | E597: =IF(OR(UPPER(TRIM(Raw_Data!D588))="M",UPPER(TRIM(Raw_Data!D588))="MALE"),"Male","Female") -> Male | F597: =PROPER(TRIM(Raw_Data!E588)) -> Amaravati | G597: =PROPER(TRIM(Raw_Data!F588)) -> Kerala | H597: =PROPER(TRIM(Raw_Data!G588)) -> Mathematics | I597: =PROPER(TRIM(Raw_Data!H588)) -> Mumbai West | J597: =IF(LEN(TRIM(Raw_Data!I588))=4,VALUE(TRIM(Raw_Data!I588)),IF(ISNUMBER(IFERROR(VALUE(MID(TRIM(Raw_Data!I588),1,4)),"NA")),VALUE(MID(TRIM(Raw_Data!I588),1,4)),VALUE(RIGHT(TRIM(Raw_Data!I588),4)))) -> 2024 | K597: =PROPER(TRIM(Raw_Data!J588)) -> Government Employee | L597: =IF(C597<10,"Under 10",IF(C597<=13,"10-13",IF(C597<=16,"14-16",IF(C597<=19,"17-19","20+")))) -> 10-13 | M597: =IF(OR(L597="Under 10",L597="10-13"),"Kids",IF(OR(L597="14-16",L597="17-19"),"Teens","Adult Learners")) -> Kids | N597: =IF(ISNUMBER(SEARCH("NON",UPPER(Raw_Data!M588))),"Non-Premium Learner","Premium Learner") -> Non-Premium Learner | O597: =PROPER(TRIM(Raw_Data!N588)) -> Both App & Web | P597: =IF(Raw_Data!O588="",$C$7,Raw_Data!O588) -> 88995.56 | Q597: =IF(Raw_Data!O588="","Missing-Imputed","Original") -> Original | R597: =Raw_Data!P588 -> 44.6 | S597: =Raw_Data!Q588 -> 46584.67 | T597: =IF(Raw_Data!R588="","Unknown",IF(ISNUMBER(SEARCH("ACT",UPPER(Raw_Data!R588))),"Active",IF(ISNUMBER(SEARCH("CLOS",UPPER(Raw_Data!R588))),"Closed","None"))) -> Unknown | U597: =IF(Raw_Data!S2="",VALUE($C$8),VALUE(Raw_Data!S2)) -> 306 | V597: =IF(Raw_Data!S588="","Missing-Imputed","Original") -> Original | W597: =Raw_Data!T588 -> 80 | X597: =IF(ISNUMBER(SEARCH("Y",UPPER(TRIM(Raw_Data!U588)))),"Yes","No") -> No | Y597: =IF(ISNUMBER(SEARCH("Y",UPPER(TRIM(Raw_Data!V588)))),"Yes","No") -> No | Z597: =Raw_Data!W588 -> 3 | AA597: =Raw_Data!X588 -> 7.6 | AB597: =IF(COUNTIFS(Raw_Data!$A$2:$A$616,Raw_Data!A588)>1,"Duplicate","Unique") -> Unique | AC597: =IF(AB597="Duplicate","Review-Duplicate",IF(OR(D597<>"Original",Q597<>"Original",V597<>"Original"),"Imputed","Clean")) -> Clean
A598: =Raw_Data!A589 -> BYJ1588 | B598: =Raw_Data!B589 -> Yashasvi Deol | C598: =IF(OR(Raw_Data!C589="",Raw_Data!C589<$C$5,Raw_Data!C589>$C$6),$C$4,Raw_Data!C589) -> 20 | D598: =IF(Raw_Data!C589="","Missing-Imputed",IF(OR(Raw_Data!C589<$C$5,Raw_Data!C589>$C$6),"Outlier-Imputed","Original")) -> Original | E598: =IF(OR(UPPER(TRIM(Raw_Data!D589))="M",UPPER(TRIM(Raw_Data!D589))="MALE"),"Male","Female") -> Male | F598: =PROPER(TRIM(Raw_Data!E589)) -> Aurangabad | G598: =PROPER(TRIM(Raw_Data!F589)) -> Kerala | H598: =PROPER(TRIM(Raw_Data!G589)) -> Robotics | I598: =PROPER(TRIM(Raw_Data!H589)) -> Hyderabad Hub | J598: =IF(LEN(TRIM(Raw_Data!I589))=4,VALUE(TRIM(Raw_Data!I589)),IF(ISNUMBER(IFERROR(VALUE(MID(TRIM(Raw_Data!I589),1,4)),"NA")),VALUE(MID(TRIM(Raw_Data!I589),1,4)),VALUE(RIGHT(TRIM(Raw_Data!I589),4)))) -> 2018 | K598: =PROPER(TRIM(Raw_Data!J589)) -> Government Employee | L598: =IF(C598<10,"Under 10",IF(C598<=13,"10-13",IF(C598<=16,"14-16",IF(C598<=19,"17-19","20+")))) -> 20+ | M598: =IF(OR(L598="Under 10",L598="10-13"),"Kids",IF(OR(L598="14-16",L598="17-19"),"Teens","Adult Learners")) -> Adult Learners | N598: =IF(ISNUMBER(SEARCH("NON",UPPER(Raw_Data!M589))),"Non-Premium Learner","Premium Learner") -> Non-Premium Learner | O598: =PROPER(TRIM(Raw_Data!N589)) -> App Only | P598: =IF(Raw_Data!O589="",$C$7,Raw_Data!O589) -> 80612.2 | Q598: =IF(Raw_Data!O589="","Missing-Imputed","Original") -> Original | R598: =Raw_Data!P589 -> 64.4 | S598: =Raw_Data!Q589 -> 9056.87 | T598: =IF(Raw_Data!R589="","Unknown",IF(ISNUMBER(SEARCH("ACT",UPPER(Raw_Data!R589))),"Active",IF(ISNUMBER(SEARCH("CLOS",UPPER(Raw_Data!R589))),"Closed","None"))) -> Active | U598: =IF(Raw_Data!S589="",$C$8,VALUE(Raw_Data!S589)) -> 330 | V598: =IF(Raw_Data!S589="","Missing-Imputed","Original") -> Original | W598: =Raw_Data!T589 -> 40 | X598: =IF(ISNUMBER(SEARCH("Y",UPPER(TRIM(Raw_Data!U589)))),"Yes","No") -> Yes | Y598: =IF(ISNUMBER(SEARCH("Y",UPPER(TRIM(Raw_Data!V589)))),"Yes","No") -> Yes | Z598: =Raw_Data!W589 -> 2 | AA598: =Raw_Data!X589 -> 1.7 | AB598: =IF(COUNTIFS(Raw_Data!$A$2:$A$616,Raw_Data!A589)>1,"Duplicate","Unique") -> Unique | AC598: =IF(AB598="Duplicate","Review-Duplicate",IF(OR(D598<>"Original",Q598<>"Original",V598<>"Original"),"Imputed","Clean")) -> Clean
A599: =Raw_Data!A590 -> BYJ1589 | B599: =Raw_Data!B590 -> Radhika De | C599: =IF(OR(Raw_Data!C590="",Raw_Data!C590<$C$5,Raw_Data!C590>$C$6),$C$4,Raw_Data!C590) -> 17 | D599: =IF(Raw_Data!C590="","Missing-Imputed",IF(OR(Raw_Data!C590<$C$5,Raw_Data!C590>$C$6),"Outlier-Imputed","Original")) -> Original | E599: =IF(OR(UPPER(TRIM(Raw_Data!D590))="M",UPPER(TRIM(Raw_Data!D590))="MALE"),"Male","Female") -> Male | F599: =PROPER(TRIM(Raw_Data!E590)) -> Jalna | G599: =PROPER(TRIM(Raw_Data!F590)) -> Tamil Nadu | H599: =PROPER(TRIM(Raw_Data!G590)) -> Mathematics | I599: =PROPER(TRIM(Raw_Data!H590)) -> Jaipur Center | J599: =IF(LEN(TRIM(Raw_Data!I590))=4,VALUE(TRIM(Raw_Data!I590)),IF(ISNUMBER(IFERROR(VALUE(MID(TRIM(Raw_Data!I590),1,4)),"NA")),VALUE(MID(TRIM(Raw_Data!I590),1,4)),VALUE(RIGHT(TRIM(Raw_Data!I590),4)))) -> 2022 | K599: =PROPER(TRIM(Raw_Data!J590)) -> Salaried | L599: =IF(C599<10,"Under 10",IF(C599<=13,"10-13",IF(C599<=16,"14-16",IF(C599<=19,"17-19","20+")))) -> 17-19 | M599: =IF(OR(L599="Under 10",L599="10-13"),"Kids",IF(OR(L599="14-16",L599="17-19"),"Teens","Adult Learners")) -> Teens | N599: =IF(ISNUMBER(SEARCH("NON",UPPER(Raw_Data!M590))),"Non-Premium Learner","Premium Learner") -> Premium Learner | O599: =PROPER(TRIM(Raw_Data!N590)) -> Both App & Web | P599: =IF(Raw_Data!O590="",$C$7,Raw_Data!O590) -> 91545.64 | Q599: =IF(Raw_Data!O590="","Missing-Imputed","Original") -> Original | R599: =Raw_Data!P590 -> 74 | S599: =Raw_Data!Q590 -> 40604.12 | T599: =IF(Raw_Data!R590="","Unknown",IF(ISNUMBER(SEARCH("ACT",UPPER(Raw_Data!R590))),"Active",IF(ISNUMBER(SEARCH("CLOS",UPPER(Raw_Data!R590))),"Closed","None"))) -> None | U599: =IF(Raw_Data!S590="",$C$8,VALUE(Raw_Data!S590)) -> #VALUE! | V599: =IF(Raw_Data!S590="","Missing-Imputed","Original") -> Original | W599: =Raw_Data!T590 -> 21 | X599: =IF(ISNUMBER(SEARCH("Y",UPPER(TRIM(Raw_Data!U590)))),"Yes","No") -> No | Y599: =IF(ISNUMBER(SEARCH("Y",UPPER(TRIM(Raw_Data!V590)))),"Yes","No") -> No | Z599: =Raw_Data!W590 -> 1 | AA599: =Raw_Data!X590 -> 3 | AB599: =IF(COUNTIFS(Raw_Data!$A$2:$A$616,Raw_Data!A590)>1,"Duplicate","Unique") -> Unique | AC599: =IF(AB599="Duplicate","Review-Duplicate",IF(OR(D599<>"Original",Q599<>"Original",V599<>"Original"),"Imputed","Clean")) -> Clean
A600: =Raw_Data!A591 -> BYJ1590 | B600: =Raw_Data!B591 -> Divya Ramaswamy | C600: =IF(OR(Raw_Data!C591="",Raw_Data!C591<$C$5,Raw_Data!C591>$C$6),$C$4,Raw_Data!C591) -> 41 | D600: =IF(Raw_Data!C591="","Missing-Imputed",IF(OR(Raw_Data!C591<$C$5,Raw_Data!C591>$C$6),"Outlier-Imputed","Original")) -> Original | E600: =IF(OR(UPPER(TRIM(Raw_Data!D591))="M",UPPER(TRIM(Raw_Data!D591))="MALE"),"Male","Female") -> Female | F600: =PROPER(TRIM(Raw_Data!E591)) -> Ratlam | G600: =PROPER(TRIM(Raw_Data!F591)) -> Karnataka | H600: =PROPER(TRIM(Raw_Data!G591)) -> Coding | I600: =PROPER(TRIM(Raw_Data!H591)) -> Ahmedabad Center | J600: =IF(LEN(TRIM(Raw_Data!I591))=4,VALUE(TRIM(Raw_Data!I591)),IF(ISNUMBER(IFERROR(VALUE(MID(TRIM(Raw_Data!I591),1,4)),"NA")),VALUE(MID(TRIM(Raw_Data!I591),1,4)),VALUE(RIGHT(TRIM(Raw_Data!I591),4)))) -> 2020 | K600: =PROPER(TRIM(Raw_Data!J591)) -> Business | L600: =IF(C600<10,"Under 10",IF(C600<=13,"10-13",IF(C600<=16,"14-16",IF(C600<=19,"17-19","20+")))) -> 20+ | M600: =IF(OR(L600="Under 10",L600="10-13"),"Kids",IF(OR(L600="14-16",L600="17-19"),"Teens","Adult Learners")) -> Adult Learners | N600: =IF(ISNUMBER(SEARCH("NON",UPPER(Raw_Data!M591))),"Non-Premium Learner","Premium Learner") -> Non-Premium Learner | O600: =PROPER(TRIM(Raw_Data!N591)) -> Both App & Web | P600: =IF(Raw_Data!O591="",$C$7,Raw_Data!O591) -> 50876.87 | Q600: =IF(Raw_Data!O591="","Missing-Imputed","Original") -> Original | R600: =Raw_Data!P591 -> 12.3 | S600: =Raw_Data!Q591 -> 218.99 | T600: =IF(Raw_Data!R591="","Unknown",IF(ISNUMBER(SEARCH("ACT",UPPER(Raw_Data!R591))),"Active",IF(ISNUMBER(SEARCH("CLOS",UPPER(Raw_Data!R591))),"Closed","None"))) -> None | U600: =IF(Raw_Data!S591="",$C$8,VALUE(Raw_Data!S591)) -> 768 | V600: =IF(Raw_Data!S591="","Missing-Imputed","Original") -> Original | W600: =Raw_Data!T591 -> 103 | X600: =IF(ISNUMBER(SEARCH("Y",UPPER(TRIM(Raw_Data!U591)))),"Yes","No") -> Yes | Y600: =IF(ISNUMBER(SEARCH("Y",UPPER(TRIM(Raw_Data!V591)))),"Yes","No") -> No | Z600: =Raw_Data!W591 -> 3 | AA600: =Raw_Data!X591 -> 8.6 | AB600: =IF(COUNTIFS(Raw_Data!$A$2:$A$616,Raw_Data!A591)>1,"Duplicate","Unique") -> Unique | AC600: =IF(AB600="Duplicate","Review-Duplicate",IF(OR(D600<>"Original",Q600<>"Original",V600<>"Original"),"Imputed","Clean")) -> Clean
A601: =Raw_Data!A592 -> BYJ1591 | B601: =Raw_Data!B592 -> Anita Kaur | C601: =IF(OR(Raw_Data!C592="",Raw_Data!C592<$C$5,Raw_Data!C592>$C$6),$C$4,Raw_Data!C592) -> 10 | D601: =IF(Raw_Data!C592="","Missing-Imputed",IF(OR(Raw_Data!C592<$C$5,Raw_Data!C592>$C$6),"Outlier-Imputed","Original")) -> Original | E601: =IF(OR(UPPER(TRIM(Raw_Data!D592))="M",UPPER(TRIM(Raw_Data!D592))="MALE"),"Male","Female") -> Female | F601: =PROPER(TRIM(Raw_Data!E592)) -> Panihati | G601: =PROPER(TRIM(Raw_Data!F592)) -> Tamil Nadu | H601: =PROPER(TRIM(Raw_Data!G592)) -> Robotics | I601: =PROPER(TRIM(Raw_Data!H592)) -> Kolkata Main | J601: =IF(LEN(TRIM(Raw_Data!I592))=4,VALUE(TRIM(Raw_Data!I592)),IF(ISNUMBER(IFERROR(VALUE(MID(TRIM(Raw_Data!I592),1,4)),"NA")),VALUE(MID(TRIM(Raw_Data!I592),1,4)),VALUE(RIGHT(TRIM(Raw_Data!I592),4)))) -> 2022 | K601: =PROPER(TRIM(Raw_Data!J592)) -> Salaried | L601: =IF(C601<10,"Under 10",IF(C601<=13,"10-13",IF(C601<=16,"14-16",IF(C601<=19,"17-19","20+")))) -> 10-13 | M601: =IF(OR(L601="Under 10",L601="10-13"),"Kids",IF(OR(L601="14-16",L601="17-19"),"Teens","Adult Learners")) -> Kids | N601: =IF(ISNUMBER(SEARCH("NON",UPPER(Raw_Data!M592))),"Non-Premium Learner","Premium Learner") -> Premium Learner | O601: =PROPER(TRIM(Raw_Data!N592)) -> Web Only | P601: =IF(Raw_Data!O592="",$C$7,Raw_Data!O592) -> 48368.17 | Q601: =IF(Raw_Data!O592="","Missing-Imputed","Original") -> Original | R601: =Raw_Data!P592 -> 11.8 | S601: =Raw_Data!Q592 -> 50443.41 | T601: =IF(Raw_Data!R592="","Unknown",IF(ISNUMBER(SEARCH("ACT",UPPER(Raw_Data!R592))),"Active",IF(ISNUMBER(SEARCH("CLOS",UPPER(Raw_Data!R592))),"Closed","None"))) -> Active | U601: =IF(Raw_Data!S592="",$C$8,VALUE(Raw_Data!S592)) -> 301 | V601: =IF(Raw_Data!S592="","Missing-Imputed","Original") -> Original | W601: =Raw_Data!T592 -> 138 | X601: =IF(ISNUMBER(SEARCH("Y",UPPER(TRIM(Raw_Data!U592)))),"Yes","No") -> No | Y601: =IF(ISNUMBER(SEARCH("Y",UPPER(TRIM(Raw_Data!V592)))),"Yes","No") -> No | Z601: =Raw_Data!W592 -> 5 | AA601: =Raw_Data!X592 -> 4.5 | AB601: =IF(COUNTIFS(Raw_Data!$A$2:$A$616,Raw_Data!A592)>1,"Duplicate","Unique") -> Unique | AC601: =IF(AB601="Duplicate","Review-Duplicate",IF(OR(D601<>"Original",Q601<>"Original",V601<>"Original"),"Imputed","Clean")) -> Clean
